<mujoco model="unnamed_model">
  <default>
    <default class="/"/>
  </default>
  <worldbody>
    <geom name="//unnamed_geom_0" class="/" type="plane" size="100 100 0.10000000000000001" pos="0 0 -3.2997274786730646"/>
    <body name="body0" pos="0 0 0">
      <joint name="//unnamed_joint_0" class="/" type="free"/>
      <geom name="//unnamed_geom_1" class="/" type="sphere" size="0.15849821030498257 0.15849821030498257 0.15849821030498257" pos="0 0 0.15849821030498257"/>
      <body name="body1" pos="0 0.69971761403565857 0">
        <geom name="//unnamed_geom_2" class="/" type="sphere" size="0.54121940373067601 0.54121940373067601 0.54121940373067601"/>
        <joint name="//unnamed_joint_1" class="/" type="hinge" axis="0 1 0"/>
      </body>
      <body name="body2" pos="0 -1.0923782632524839 0">
        <geom name="//unnamed_geom_3" class="/" type="sphere" size="0.9338800529475012 0.9338800529475012 0.9338800529475012"/>
        <joint name="//unnamed_joint_2" class="/" type="ball" axis="0 -1 0"/>
      </body>
      <body name="body3" pos="1.0804762540317459 0 0">
        <geom name="//unnamed_geom_4" class="/" type="sphere" size="0.92197804372676329 0.92197804372676329 0.92197804372676329"/>
        <joint name="//unnamed_joint_3" class="/" type="hinge" axis="1 0 0"/>
        <body name="body4" pos="0 0 -1.6108527611999139">
          <geom name="//unnamed_geom_5" class="/" type="sphere" size="0.68887471747315066 0.68887471747315066 0.68887471747315066"/>
          <joint name="//unnamed_joint_4" class="/" type="ball" axis="0 0 -1"/>
        </body>
      </body>
    </body>
  </worldbody>
  <actuator>
    <motor name="//unnamed_actuator_0" class="/" ctrllimited="true" ctrlrange="-1 1" joint="//unnamed_joint_0"/>
    <motor name="//unnamed_actuator_1" class="/" ctrllimited="true" ctrlrange="-1 1" joint="//unnamed_joint_1"/>
    <motor name="//unnamed_actuator_2" class="/" ctrllimited="true" ctrlrange="-1 1" joint="//unnamed_joint_2"/>
    <motor name="//unnamed_actuator_3" class="/" ctrllimited="true" ctrlrange="-1 1" joint="//unnamed_joint_3"/>
    <motor name="//unnamed_actuator_4" class="/" ctrllimited="true" ctrlrange="-1 1" joint="//unnamed_joint_4"/>
  </actuator>
</mujoco>
